Traceback (most recent call last):
  File "/opt/anaconda3/lib/python3.9/site-packages/jupyter_cache/executors/utils.py", line 51, in single_nb_execution
    executenb(
  File "/opt/anaconda3/lib/python3.9/site-packages/nbclient/client.py", line 1204, in execute
    return NotebookClient(nb=nb, resources=resources, km=km, **kwargs).execute()
  File "/opt/anaconda3/lib/python3.9/site-packages/nbclient/util.py", line 84, in wrapped
    return just_run(coro(*args, **kwargs))
  File "/opt/anaconda3/lib/python3.9/site-packages/nbclient/util.py", line 62, in just_run
    return loop.run_until_complete(coro)
  File "/opt/anaconda3/lib/python3.9/asyncio/base_events.py", line 647, in run_until_complete
    return future.result()
  File "/opt/anaconda3/lib/python3.9/site-packages/nbclient/client.py", line 663, in async_execute
    await self.async_execute_cell(
  File "/opt/anaconda3/lib/python3.9/site-packages/nbclient/client.py", line 965, in async_execute_cell
    await self._check_raise_for_error(cell, cell_index, exec_reply)
  File "/opt/anaconda3/lib/python3.9/site-packages/nbclient/client.py", line 862, in _check_raise_for_error
    raise CellExecutionError.from_cell_and_msg(cell, exec_reply_content)
nbclient.exceptions.CellExecutionError: An error occurred while executing the following cell:
------------------
df.iloc[1,'Titles']
------------------

[0;31m---------------------------------------------------------------------------[0m
[0;31mValueError[0m                                Traceback (most recent call last)
File [0;32m/opt/anaconda3/lib/python3.9/site-packages/pandas/core/indexing.py:769[0m, in [0;36m_LocationIndexer._validate_tuple_indexer[0;34m(self, key)[0m
[1;32m    768[0m [38;5;28;01mtry[39;00m:
[0;32m--> 769[0m     [38;5;28;43mself[39;49m[38;5;241;43m.[39;49m[43m_validate_key[49m[43m([49m[43mk[49m[43m,[49m[43m [49m[43mi[49m[43m)[49m
[1;32m    770[0m [38;5;28;01mexcept[39;00m [38;5;167;01mValueError[39;00m [38;5;28;01mas[39;00m err:

File [0;32m/opt/anaconda3/lib/python3.9/site-packages/pandas/core/indexing.py:1378[0m, in [0;36m_iLocIndexer._validate_key[0;34m(self, key, axis)[0m
[1;32m   1377[0m [38;5;28;01melse[39;00m:
[0;32m-> 1378[0m     [38;5;28;01mraise[39;00m [38;5;167;01mValueError[39;00m([38;5;124mf[39m[38;5;124m"[39m[38;5;124mCan only index by location with a [[39m[38;5;132;01m{[39;00m[38;5;28mself[39m[38;5;241m.[39m_valid_types[38;5;132;01m}[39;00m[38;5;124m][39m[38;5;124m"[39m)

[0;31mValueError[0m: Can only index by location with a [integer, integer slice (START point is INCLUDED, END point is EXCLUDED), listlike of integers, boolean array]

The above exception was the direct cause of the following exception:

[0;31mValueError[0m                                Traceback (most recent call last)
Input [0;32mIn [31][0m, in [0;36m<cell line: 1>[0;34m()[0m
[0;32m----> 1[0m [43mdf[49m[38;5;241;43m.[39;49m[43miloc[49m[43m[[49m[38;5;241;43m1[39;49m[43m,[49m[38;5;124;43m'[39;49m[38;5;124;43mTitles[39;49m[38;5;124;43m'[39;49m[43m][49m

File [0;32m/opt/anaconda3/lib/python3.9/site-packages/pandas/core/indexing.py:961[0m, in [0;36m_LocationIndexer.__getitem__[0;34m(self, key)[0m
[1;32m    959[0m     [38;5;28;01mif[39;00m [38;5;28mself[39m[38;5;241m.[39m_is_scalar_access(key):
[1;32m    960[0m         [38;5;28;01mreturn[39;00m [38;5;28mself[39m[38;5;241m.[39mobj[38;5;241m.[39m_get_value([38;5;241m*[39mkey, takeable[38;5;241m=[39m[38;5;28mself[39m[38;5;241m.[39m_takeable)
[0;32m--> 961[0m     [38;5;28;01mreturn[39;00m [38;5;28;43mself[39;49m[38;5;241;43m.[39;49m[43m_getitem_tuple[49m[43m([49m[43mkey[49m[43m)[49m
[1;32m    962[0m [38;5;28;01melse[39;00m:
[1;32m    963[0m     [38;5;66;03m# we by definition only have the 0th axis[39;00m
[1;32m    964[0m     axis [38;5;241m=[39m [38;5;28mself[39m[38;5;241m.[39maxis [38;5;129;01mor[39;00m [38;5;241m0[39m

File [0;32m/opt/anaconda3/lib/python3.9/site-packages/pandas/core/indexing.py:1458[0m, in [0;36m_iLocIndexer._getitem_tuple[0;34m(self, tup)[0m
[1;32m   1456[0m [38;5;28;01mdef[39;00m [38;5;21m_getitem_tuple[39m([38;5;28mself[39m, tup: [38;5;28mtuple[39m):
[0;32m-> 1458[0m     tup [38;5;241m=[39m [38;5;28;43mself[39;49m[38;5;241;43m.[39;49m[43m_validate_tuple_indexer[49m[43m([49m[43mtup[49m[43m)[49m
[1;32m   1459[0m     [38;5;28;01mwith[39;00m suppress(IndexingError):
[1;32m   1460[0m         [38;5;28;01mreturn[39;00m [38;5;28mself[39m[38;5;241m.[39m_getitem_lowerdim(tup)

File [0;32m/opt/anaconda3/lib/python3.9/site-packages/pandas/core/indexing.py:771[0m, in [0;36m_LocationIndexer._validate_tuple_indexer[0;34m(self, key)[0m
[1;32m    769[0m         [38;5;28mself[39m[38;5;241m.[39m_validate_key(k, i)
[1;32m    770[0m     [38;5;28;01mexcept[39;00m [38;5;167;01mValueError[39;00m [38;5;28;01mas[39;00m err:
[0;32m--> 771[0m         [38;5;28;01mraise[39;00m [38;5;167;01mValueError[39;00m(
[1;32m    772[0m             [38;5;124m"[39m[38;5;124mLocation based indexing can only have [39m[38;5;124m"[39m
[1;32m    773[0m             [38;5;124mf[39m[38;5;124m"[39m[38;5;124m[[39m[38;5;132;01m{[39;00m[38;5;28mself[39m[38;5;241m.[39m_valid_types[38;5;132;01m}[39;00m[38;5;124m] types[39m[38;5;124m"[39m
[1;32m    774[0m         ) [38;5;28;01mfrom[39;00m [38;5;21;01merr[39;00m
[1;32m    775[0m [38;5;28;01mreturn[39;00m key

[0;31mValueError[0m: Location based indexing can only have [integer, integer slice (START point is INCLUDED, END point is EXCLUDED), listlike of integers, boolean array] types
ValueError: Location based indexing can only have [integer, integer slice (START point is INCLUDED, END point is EXCLUDED), listlike of integers, boolean array] types

